<?xml version="1.0" ?>
<robot name="ur5">
  <!-- base link -->
  <!-- links: main serial chain -->
  <link name="right_base_link"/>
  <link name="right_base_link_inertia">
    <visual>
      <origin rpy="0 0 3.141592653589793" xyz="0 0 0"/>
      <geometry>
        <mesh filename="ur5_meshes/visual/base.dae"/>
      </geometry>
    </visual>
    <collision>
      <origin rpy="0 0 3.141592653589793" xyz="0 0 0"/>
      <geometry>
        <mesh filename="ur5_meshes/collision/base.stl"/>
      </geometry>
    </collision>
    <inertial>
      <mass value="4.0"/>
      <origin rpy="0 0 0" xyz="0 0 0"/>
      <inertia ixx="0.00443333156" ixy="0.0" ixz="0.0" iyy="0.00443333156" iyz="0.0" izz="0.0072"/>
    </inertial>
  </link>
  <link name="right_shoulder_link">
    <visual>
      <origin rpy="0 0 3.141592653589793" xyz="0 0 0"/>
      <geometry>
        <mesh filename="ur5_meshes/visual/shoulder.dae"/>
      </geometry>
    </visual>
    <collision>
      <origin rpy="0 0 3.141592653589793" xyz="0 0 0"/>
      <geometry>
        <mesh filename="ur5_meshes/collision/shoulder.stl"/>
      </geometry>
    </collision>
    <inertial>
      <mass value="3.7"/>
      <origin rpy="0 0 0" xyz="0 0 0"/>
      <inertia ixx="0.014972352344389999" ixy="0.0" ixz="0.0" iyy="0.014972352344389999" iyz="0.0" izz="0.01040625"/>
    </inertial>
  </link>
  <link name="right_upper_arm_link">
    <visual>
      <origin rpy="1.5707963267948966 0 -1.5707963267948966" xyz="0 0 0.13585"/>
      <geometry>
        <mesh filename="ur5_meshes/visual/upperarm.dae"/>
      </geometry>
    </visual>
    <collision>
      <origin rpy="1.5707963267948966 0 -1.5707963267948966" xyz="0 0 0.13585"/>
      <geometry>
        <mesh filename="ur5_meshes/collision/upperarm_lower.stl"/>
      </geometry>
    </collision>
    <collision>
      <origin rpy="1.5707963267948966 0 -1.5707963267948966" xyz="0 0 0.13585"/>
      <geometry>
        <mesh filename="ur5_meshes/collision/upperarm_middle.stl"/>
      </geometry>
    </collision>
    <collision>
      <origin rpy="1.5707963267948966 0 -1.5707963267948966" xyz="0 0 0.13585"/>
      <geometry>
        <mesh filename="ur5_meshes/collision/upperarm_upper.stl"/>
      </geometry>
    </collision>
    <inertial>
      <mass value="8.393"/>
      <origin rpy="0 1.5707963267948966 0" xyz="-0.2125 0.0 0.136"/>
      <inertia ixx="0.1338857818623325" ixy="0.0" ixz="0.0" iyy="0.1338857818623325" iyz="0.0" izz="0.0151074"/>
    </inertial>
  </link>
  <link name="right_forearm_link">
    <visual>
      <origin rpy="1.5707963267948966 0 -1.5707963267948966" xyz="0 0 0.0165"/>
      <geometry>
        <mesh filename="ur5_meshes/visual/forearm.dae"/>
      </geometry>
    </visual>
    <collision>
      <origin rpy="1.5707963267948966 0 -1.5707963267948966" xyz="0 0 0.0165"/>
      <geometry>
        <mesh filename="ur5_meshes/collision/forearm_lower.stl"/>
      </geometry>
    </collision>
    <collision>
      <origin rpy="1.5707963267948966 0 -1.5707963267948966" xyz="0 0 0.0165"/>
      <geometry>
        <mesh filename="ur5_meshes/collision/forearm_middle.stl"/>
      </geometry>
    </collision>
    <collision>
      <origin rpy="1.5707963267948966 0 -1.5707963267948966" xyz="0 0 0.0165"/>
      <geometry>
        <mesh filename="ur5_meshes/collision/forearm_upper.stl"/>
      </geometry>
    </collision>
    <inertial>
      <mass value="2.275"/>
      <origin rpy="0 1.5707963267948966 0" xyz="-0.196125 0.0 0.0165"/>
      <inertia ixx="0.03121679102890359" ixy="0.0" ixz="0.0" iyy="0.03121679102890359" iyz="0.0" izz="0.004095"/>
    </inertial>
  </link>
  <link name="right_wrist_1_link">
    <visual>
      <!-- TODO: Move this to a parameter -->
      <origin rpy="1.5707963267948966 0 0" xyz="0 0 -0.093"/>
      <geometry>
        <mesh filename="ur5_meshes/visual/wrist1.dae"/>
      </geometry>
    </visual>
    <collision>
      <origin rpy="1.5707963267948966 0 0" xyz="0 0 -0.093"/>
      <geometry>
        <mesh filename="ur5_meshes/collision/wrist1.stl"/>
      </geometry>
    </collision>
    <inertial>
      <mass value="1.219"/>
      <origin rpy="0 0 0" xyz="0 0 0"/>
      <inertia ixx="0.0020138887777775" ixy="0.0" ixz="0.0" iyy="0.0020138887777775" iyz="0.0" izz="0.0021942"/>
    </inertial>
  </link>
  <link name="right_wrist_2_link">
    <visual>
      <origin rpy="0 0 0" xyz="0 0 -0.095"/>
      <geometry>
        <mesh filename="ur5_meshes/visual/wrist2.dae"/>
      </geometry>
    </visual>
    <collision>
      <origin rpy="0 0 0" xyz="0 0 -0.095"/>
      <geometry>
        <mesh filename="ur5_meshes/collision/wrist2.stl"/>
      </geometry>
    </collision>
    <inertial>
      <mass value="1.219"/>
      <origin rpy="0 0 0" xyz="0 0 0"/>
      <inertia ixx="0.0018310388509175" ixy="0.0" ixz="0.0" iyy="0.0018310388509175" iyz="0.0" izz="0.0021942"/>
    </inertial>
  </link>
  <link name="right_wrist_3_link">
    <visual>
      <origin rpy="1.5707963267948966 0 0" xyz="0 0 -0.0818"/>
      <geometry>
        <mesh filename="ur5_meshes/visual/wrist3.dae"/>
      </geometry>
    </visual>
    <collision>
      <origin rpy="1.5707963267948966 0 0" xyz="0 0 -0.0818"/>
      <geometry>
        <mesh filename="ur5_meshes/collision/wrist3.stl"/>
      </geometry>
    </collision>
    <inertial>
      <mass value="0.1879"/>
      <origin rpy="0 0 0" xyz="0.0 0.0 -0.01525"/>
      <inertia ixx="8.062472608343e-05" ixy="0.0" ixz="0.0" iyy="8.062472608343e-05" iyz="0.0" izz="0.0001321171875"/>
    </inertial>
  </link>
  <!-- joints: main serial chain -->
  <joint name="right_base_link-base_link_inertia" type="fixed">
    <parent link="right_base_link"/>
    <child link="right_base_link_inertia"/>
    <!-- 'base_link' is REP-103 aligned (so X+ forward), while the internal
           frames of the robot/controller have X+ pointing backwards.
           Use the joint between 'base_link' and 'base_link_inertia' (a dummy
           link/frame) to introduce the necessary rotation over Z (of pi rad).
      -->
    <origin rpy="0 0 3.141592653589793" xyz="0 0 0"/>
  </joint>
  <joint name="right_shoulder_pan_joint" type="revolute">
    <parent link="right_base_link_inertia"/>
    <child link="right_shoulder_link"/>
    <origin rpy="0 0 6.935093637945505e-05" xyz="0 0 0.08949928559905179"/>
    <axis xyz="0 0 1"/>
    <limit effort="150.0" lower="-3.141592653589793" upper="3.141592653589793" velocity="3.141592653589793"/>
    <dynamics damping="0" friction="0"/>
  </joint>
  <joint name="right_shoulder_lift_joint" type="revolute">
    <parent link="right_shoulder_link"/>
    <child link="right_upper_arm_link"/>
    <origin rpy="1.569776430478979 0 -1.899595783444728e-05" xyz="-4.453187360131969e-05 0 0"/>
    <axis xyz="0 0 1"/>
    <limit effort="150.0" lower="-3.141592653589793" upper="3.141592653589793" velocity="3.141592653589793"/>
    <dynamics damping="0" friction="0"/>
  </joint>
  <joint name="right_elbow_joint" type="revolute">
    <parent link="right_upper_arm_link"/>
    <child link="right_forearm_link"/>
    <origin rpy="0.003664895000787752 0.003110587533505237 -1.094175347315775e-05" xyz="-0.4255955178735976 0 0"/>
    <axis xyz="0 0 1"/>
    <limit effort="150.0" lower="-3.141592653589793" upper="3.141592653589793" velocity="3.141592653589793"/>
    <dynamics damping="0" friction="0"/>
  </joint>
  <joint name="right_wrist_1_joint" type="revolute">
    <parent link="right_forearm_link"/>
    <child link="right_wrist_1_link"/>
    <origin rpy="0.005347748217401119 0.0006785171055329065 -2.742538745494148e-05" xyz="-0.3924311684839673 -0.0005944496110317049 0.1111578032629135"/>
    <axis xyz="0 0 1"/>
    <limit effort="28.0" lower="-3.141592653589793" upper="3.141592653589793" velocity="3.141592653589793"/>
    <dynamics damping="0" friction="0"/>
  </joint>
  <joint name="right_wrist_2_joint" type="revolute">
    <parent link="right_wrist_1_link"/>
    <child link="right_wrist_2_link"/>
    <origin rpy="1.569468403067662 0 -9.542494196330857e-05" xyz="2.941862599780075e-05 -0.09489788806426759 0.0001260172312971319"/>
    <axis xyz="0 0 1"/>
    <limit effort="28.0" lower="-3.141592653589793" upper="3.141592653589793" velocity="3.141592653589793"/>
    <dynamics damping="0" friction="0"/>
  </joint>
  <joint name="right_wrist_3_joint" type="revolute">
    <parent link="right_wrist_2_link"/>
    <child link="right_wrist_3_link"/>
    <origin rpy="1.572087084765102 3.141592653589793 3.141548784260287" xyz="2.687562318826077e-05 0.0824693622601854 0.0001064480457512508"/>
    <axis xyz="0 0 1"/>
    <limit effort="28.0" lower="-3.141592653589793" upper="3.141592653589793" velocity="3.141592653589793"/>
    <dynamics damping="0" friction="0"/>
  </joint>
  <!-- ROS-Industrial 'flange' frame: attachment point for EEF models -->
  <link name="right_flange"/>
  <joint name="right_wrist_3-flange" type="fixed">
    <parent link="right_wrist_3_link"/>
    <child link="right_flange"/>
    <origin rpy="0 -1.5707963267948966 -1.5707963267948966" xyz="0 0 0"/>
  </joint>
  <!-- ROS-Industrial 'tool0' frame: all-zeros tool frame -->
  <link name="right_tool0"/>
  <joint name="right_flange-tool0" type="fixed">
    <!-- default toolframe: X+ left, Y+ up, Z+ front -->
    <origin rpy="1.5707963267948966 0 1.5707963267948966" xyz="0 0 0"/>
    <parent link="right_flange"/>
    <child link="right_tool0"/>
  </joint>
  <!-- mount the fts to the robot -->
  <joint name="right_ft300_fix" type="fixed">
    <origin rpy="0 0 -1.5707963267948966" xyz="0 0 -0.004"/>
    <parent link="right_tool0"/>
    <child link="right_ft300_mounting_plate"/>
  </joint>
  <!-- Link representing the FT300 force-torque sensor -->
  <link name="right_ft300_sensor">
    <inertial>
      <origin rpy="0 0 0" xyz="0 0 -0.017"/>
      <mass value="0.300"/>
      <inertia ixx="0.000262" ixy="0" ixz="1e-06" iyx="0" iyy="0.000265" iyz="1e-06" izx="-1e-06" izy="1e-06" izz="0.000219"/>
    </inertial>
    <visual>
      <origin rpy="0 0 0" xyz="0 0 0"/>
      <geometry>
        <mesh filename="sensor_meshes/visual/robotiq_ft300.STL"/>
      </geometry>
      <material name="Robotiq-Black">
        <color rgba="0.2 0.2 0.2 1.0"/>
      </material>
    </visual>
    <collision>
      <origin rpy="0 0 0" xyz="0 0 0"/>
      <geometry>
        <mesh filename="sensor_meshes/collision/robotiq_ft300.STL"/>
      </geometry>
    </collision>
  </link>
  <!-- Link representing the FT300 mounting plate -->
  <link name="right_ft300_mounting_plate">
    <visual>
      <origin rpy="0 0 0" xyz="0 0 0"/>
      <geometry>
        <mesh filename="sensor_meshes/visual/mountings/robotiq_ft300_coupling.STL"/>
      </geometry>
      <material name="Robotiq-Grey">
        <color rgba="0.4 0.4 0.4 1.0"/>
      </material>
    </visual>
    <collision>
      <origin rpy="0 0 0" xyz="0 0 0"/>
      <geometry>
        <mesh filename="sensor_meshes/collision/mountings/robotiq_ft300_coupling.STL"/>
      </geometry>
    </collision>
  </link>
  <!-- Connect force sensor with mounting/coupling plate -->
  <joint name="right_ft300_mounting_plate_joint" type="fixed">
    <origin rpy="0 3.141592653589793 0" xyz="0 0 0.0415"/>
    <parent link="right_ft300_mounting_plate"/>
    <child link="right_ft300_sensor"/>
  </joint>
  <!-- FORCE REFERENCE FRAME _______________________________________________________________________________
            As specified in the documentation:
            - The Z axis passes through the center of the depression with positive direction in the tool direction.
            - The X axis traces a symmetric line centered on the connector; the positive direction
                points the opposite way away from the connector.
            - The Y axis uses the right hand thumb rule according to X-Z. -->
  <joint name="right_measurment_joint" type="fixed">
    <origin rpy="0 3.141592653589793 -1.5707963267948966" xyz="0 0 0"/>
    <parent link="right_ft300_sensor"/>
    <child link="right_robotiq_ft_frame_id"/>
  </joint>
  <link name="right_robotiq_ft_frame_id"/>
  <!-- tool frame -->
  <link name="right_tool"/>
  <joint name="right_tool_joint" type="fixed">
    <origin rpy="0 0 -3.141592653589793" xyz="0 0 0"/>
    <parent link="right_robotiq_ft_frame_id"/>
    <child link="right_tool"/>
  </joint>
  <!-- ============================= HAND and FINGERS ============================== -->
  <!-- PALM -->
  <link name="right_gripper_palm_link">
    <visual>
      <geometry>
        <mesh filename="allegro_meshes/base_link.obj"/>
      </geometry>
    </visual>
    <collision>
      <origin rpy="0 0 0" xyz="-0.009300 0 -0.0475"/>
      <geometry>
        <box size="0.0408 0.1130 0.095"/>
      </geometry>
    </collision>
    <inertial>
      <origin rpy="0 0 0" xyz="0 0 0.0475"/>
      <mass value="0.4154"/>
      <inertia ixx="1e-4" ixy="0.0" ixz="0.0" iyy="1e-4" iyz="0.0" izz="1e-4"/>
    </inertial>
  </link>

  <link name="right_gripper_wrist_link"/>
  <joint name="right_gripper_wrist_joint" type="fixed">
    <origin rpy="0 0 0" xyz="0 0 -0.03"/>
    <parent link="right_gripper_palm_link"/>
    <child link="right_gripper_wrist_link"/>
  </joint>
  <!-- END THUMB MACRO -->
  <!-- [[END]] THREE FINGER MACRO -->
  <!-- [LINK 0, 4, 8] -->
  <link name="right_gripper_link_00">
    <visual>
      <geometry>
        <mesh filename="allegro_meshes/link_0_0.obj"/>
      </geometry>
    </visual>
    <collision>
      <geometry>
        <box size="0.0196 0.0275 0.0164"/>
      </geometry>
      <origin rpy="0 0 0" xyz="0 0 0.0082"/>
    </collision>
    <inertial>
      <mass value="0.0119"/>
      <origin rpy="0 0 0" xyz="0 0 0"/>
      <inertia ixx="1.016e-06" ixy="0.0" ixz="0.0" iyy="6.476e-07" iyz="0.0" izz="1.016e-06"/>
    </inertial>
  </link>
  <joint name="right_gripper_joint_00" type="revolute">
    <axis xyz="0 0 1"/>
    <limit effort="0.35" lower="-0.47" upper="0.47" velocity="6.283"/>
    <parent link="right_gripper_palm_link"/>
    <child link="right_gripper_link_00"/>
    <origin rpy="-0.08726646254999999 0 0" xyz="0 0.0435 -0.001542"/>
    <dynamics damping="0.1" friction="0.01"/>
  </joint>
  <!-- [LINK 1, 5, 9] -->
  <link name="right_gripper_link_01">
    <visual>
      <geometry>
        <mesh filename="allegro_meshes/link_1_0.obj"/>
      </geometry>
    </visual>
    <collision>
      <geometry>
        <box size="0.0196 0.0275 0.054"/>
      </geometry>
      <origin rpy="0 0 0" xyz="0 0 0.027"/>
    </collision>
    <inertial>
      <mass value="0.065"/>
      <origin rpy="0 0 0" xyz="0 0 0"/>
      <inertia ixx="7.956e-05" ixy="1.719e-05" ixz="8.758e-06" iyy="2.470e-05" iyz="2.413e-05" izz="7.956e-05"/>
    </inertial>
  </link>
  <joint name="right_gripper_joint_01" type="revolute">
    <limit effort="0.35" lower="-0.19599999999999998" upper="1.6099999999999999" velocity="6.283"/>
    <axis xyz="0 1 0"/>
    <parent link="right_gripper_link_00"/>
    <child link="right_gripper_link_01"/>
    <origin xyz="0 0 0.0164"/>
    <dynamics damping="0.1" friction="0.01"/>
  </joint>
  <!-- [LINK 2, 6, 10]-->
  <link name="right_gripper_link_02">
    <visual>
      <geometry>
        <mesh filename="allegro_meshes/link_2_0.obj"/>
      </geometry>
    </visual>
    <collision>
      <geometry>
        <box size="0.0196 0.0275 0.0384"/>
      </geometry>
      <origin rpy="0 0 0" xyz="0 0 0.0192"/>
    </collision>
    <inertial>
      <mass value="0.0355"/>
      <origin rpy="0 0 0" xyz="0 0 0"/>
      <inertia ixx="2.639e-05" ixy="6.679e-06" ixz="4.783e-06" iyy="1.349e-05" iyz="9.372e-06" izz="2.639e-05"/>
    </inertial>
  </link>
  <joint name="right_gripper_joint_02" type="revolute">
    <axis xyz="0 1 0"/>
    <limit effort="0.35" lower="-0.17400000000000002" upper="1.7089999999999999" velocity="6.283"/>
    <parent link="right_gripper_link_01"/>
    <child link="right_gripper_link_02"/>
    <origin xyz="0 0 0.054"/>
    <dynamics damping="0.1" friction="0.01"/>
  </joint>
  <!-- [LINK 3, 7, 11] -->
  <link name="right_gripper_link_03">
    <visual>
      <geometry>
        <mesh filename="allegro_meshes/link_3_0.obj"/>
      </geometry>
    </visual>
    <collision>
      <geometry>
        <box size="0.0196 0.0275 0.0267"/>
      </geometry>
      <origin rpy="0 0 0" xyz="0 0 0.01335"/>
    </collision>
    <inertial>
      <mass value="0.0096"/>
      <origin rpy="0 0 0" xyz="0 0 0"/>
      <inertia ixx="4.701e-06" ixy="1.255e-06" ixz="1.293e-06" iyy="3.649e-06" iyz="1.762e-06" izz="4.701e-06"/>
    </inertial>
  </link>
  <joint name="right_gripper_joint_03" type="revolute">
    <axis xyz="0 1 0"/>
    <limit effort="0.35" lower="-0.227" upper="1.618" velocity="6.283"/>
    <parent link="right_gripper_link_02"/>
    <child link="right_gripper_link_03"/>
    <origin xyz="0 0 0.0384"/>
    <dynamics damping="0.1" friction="0.01"/>
  </joint>
  <!-- [FINGER TIP] -->
  <link name="right_gripper_link_03_tip">
    <visual>
      <geometry>
        <mesh filename="allegro_meshes/link_3_tip.stl"/>
      </geometry>
      <material name="white">
        <color rgba=".9 .9 .9 1"/>
      </material>
    </visual>
    <collision>
      <geometry>
        <sphere radius="0.012"/>
      </geometry>
    </collision>
    <inertial>
      <mass value="0.0168"/>
      <origin rpy="0 0 0" xyz="0 0 0"/>
      <inertia ixx="9.68e-07" ixy="0.0" ixz="0.0" iyy="9.68e-07" iyz="0.0" izz="9.68e-07"/>
    </inertial>
  </link>
  <joint name="right_gripper_joint_03_tip" type="fixed">
    <parent link="right_gripper_link_03"/>
    <child link="right_gripper_link_03_tip"/>
    <origin rpy="0 0 0" xyz="0 0 0.026699999999999998"/>
  </joint>
  <!-- [LINK 0, 4, 8] -->
  <link name="right_gripper_link_04">
    <visual>
      <geometry>
        <mesh filename="allegro_meshes/link_0_0.obj"/>
      </geometry>
    </visual>
    <collision>
      <geometry>
        <box size="0.0196 0.0275 0.0164"/>
      </geometry>
      <origin rpy="0 0 0" xyz="0 0 0.0082"/>
    </collision>
    <inertial>
      <mass value="0.0119"/>
      <origin rpy="0 0 0" xyz="0 0 0"/>
      <inertia ixx="1.016e-06" ixy="0.0" ixz="0.0" iyy="6.476e-07" iyz="0.0" izz="1.016e-06"/>
    </inertial>
  </link>
  <joint name="right_gripper_joint_04" type="revolute">
    <axis xyz="0 0 1"/>
    <limit effort="0.35" lower="-0.47" upper="0.47" velocity="6.283"/>
    <parent link="right_gripper_palm_link"/>
    <child link="right_gripper_link_04"/>
    <origin rpy="0.0 0 0" xyz="0 0 0.0007"/>
    <dynamics damping="0.1" friction="0.01"/>
  </joint>
  <!-- [LINK 1, 5, 9] -->
  <link name="right_gripper_link_05">
    <visual>
      <geometry>
        <mesh filename="allegro_meshes/link_1_0.obj"/>
      </geometry>
    </visual>
    <collision>
      <geometry>
        <box size="0.0196 0.0275 0.054"/>
      </geometry>
      <origin rpy="0 0 0" xyz="0 0 0.027"/>
    </collision>
    <inertial>
      <mass value="0.065"/>
      <origin rpy="0 0 0" xyz="0 0 0"/>
      <inertia ixx="7.956e-05" ixy="1.719e-05" ixz="8.758e-06" iyy="2.470e-05" iyz="2.413e-05" izz="7.956e-05"/>
    </inertial>
  </link>
  <joint name="right_gripper_joint_05" type="revolute">
    <limit effort="0.35" lower="-0.19599999999999998" upper="1.6099999999999999" velocity="6.283"/>
    <axis xyz="0 1 0"/>
    <parent link="right_gripper_link_04"/>
    <child link="right_gripper_link_05"/>
    <origin xyz="0 0 0.0164"/>
    <dynamics damping="0.1" friction="0.01"/>
  </joint>
  <!-- [LINK 2, 6, 10]-->
  <link name="right_gripper_link_06">
    <visual>
      <geometry>
        <mesh filename="allegro_meshes/link_2_0.obj"/>
      </geometry>
    </visual>
    <collision>
      <geometry>
        <box size="0.0196 0.0275 0.0384"/>
      </geometry>
      <origin rpy="0 0 0" xyz="0 0 0.0192"/>
    </collision>
    <inertial>
      <mass value="0.0355"/>
      <origin rpy="0 0 0" xyz="0 0 0"/>
      <inertia ixx="2.639e-05" ixy="6.679e-06" ixz="4.783e-06" iyy="1.349e-05" iyz="9.372e-06" izz="2.639e-05"/>
    </inertial>
  </link>
  <joint name="right_gripper_joint_06" type="revolute">
    <axis xyz="0 1 0"/>
    <limit effort="0.35" lower="-0.17400000000000002" upper="1.7089999999999999" velocity="6.283"/>
    <parent link="right_gripper_link_05"/>
    <child link="right_gripper_link_06"/>
    <origin xyz="0 0 0.054"/>
    <dynamics damping="0.1" friction="0.01"/>
  </joint>
  <!-- [LINK 3, 7, 11] -->
  <link name="right_gripper_link_07">
    <visual>
      <geometry>
        <mesh filename="allegro_meshes/link_3_0.obj"/>
      </geometry>
    </visual>
    <collision>
      <geometry>
        <box size="0.0196 0.0275 0.0267"/>
      </geometry>
      <origin rpy="0 0 0" xyz="0 0 0.01335"/>
    </collision>
    <inertial>
      <mass value="0.0096"/>
      <origin rpy="0 0 0" xyz="0 0 0"/>
      <inertia ixx="4.701e-06" ixy="1.255e-06" ixz="1.293e-06" iyy="3.649e-06" iyz="1.762e-06" izz="4.701e-06"/>
    </inertial>
  </link>
  <joint name="right_gripper_joint_07" type="revolute">
    <axis xyz="0 1 0"/>
    <limit effort="0.35" lower="-0.227" upper="1.618" velocity="6.283"/>
    <parent link="right_gripper_link_06"/>
    <child link="right_gripper_link_07"/>
    <origin xyz="0 0 0.0384"/>
    <dynamics damping="0.1" friction="0.01"/>
  </joint>
  <!-- [FINGER TIP] -->
  <link name="right_gripper_link_07_tip">
    <visual>
      <geometry>
        <mesh filename="allegro_meshes/link_3_tip.stl"/>
      </geometry>
      <material name="white">
        <color rgba=".9 .9 .9 1"/>
      </material>
    </visual>
    <collision>
      <geometry>
        <sphere radius="0.012"/>
      </geometry>
    </collision>
    <inertial>
      <mass value="0.0168"/>
      <origin rpy="0 0 0" xyz="0 0 0"/>
      <inertia ixx="9.68e-07" ixy="0.0" ixz="0.0" iyy="9.68e-07" iyz="0.0" izz="9.68e-07"/>
    </inertial>
  </link>
  <joint name="right_gripper_joint_07_tip" type="fixed">
    <parent link="right_gripper_link_07"/>
    <child link="right_gripper_link_07_tip"/>
    <origin rpy="0 0 0" xyz="0 0 0.026699999999999998"/>
  </joint>
  <!-- [LINK 0, 4, 8] -->
  <link name="right_gripper_link_08">
    <visual>
      <geometry>
        <mesh filename="allegro_meshes/link_0_0.obj"/>
      </geometry>
    </visual>
    <collision>
      <geometry>
        <box size="0.0196 0.0275 0.0164"/>
      </geometry>
      <origin rpy="0 0 0" xyz="0 0 0.0082"/>
    </collision>
    <inertial>
      <mass value="0.0119"/>
      <origin rpy="0 0 0" xyz="0 0 0"/>
      <inertia ixx="1.016e-06" ixy="0.0" ixz="0.0" iyy="6.476e-07" iyz="0.0" izz="1.016e-06"/>
    </inertial>
  </link>
  <joint name="right_gripper_joint_08" type="revolute">
    <axis xyz="0 0 1"/>
    <limit effort="0.35" lower="-0.47" upper="0.47" velocity="6.283"/>
    <parent link="right_gripper_palm_link"/>
    <child link="right_gripper_link_08"/>
    <origin rpy="0.08726646254999999 0 0" xyz="0 -0.0435 -0.001542"/>
    <dynamics damping="0.1" friction="0.01"/>
  </joint>
  <!-- [LINK 1, 5, 9] -->
  <link name="right_gripper_link_09">
    <visual>
      <geometry>
        <mesh filename="allegro_meshes/link_1_0.obj"/>
      </geometry>
    </visual>
    <collision>
      <geometry>
        <box size="0.0196 0.0275 0.054"/>
      </geometry>
      <origin rpy="0 0 0" xyz="0 0 0.027"/>
    </collision>
    <inertial>
      <mass value="0.065"/>
      <origin rpy="0 0 0" xyz="0 0 0"/>
      <inertia ixx="7.956e-05" ixy="1.719e-05" ixz="8.758e-06" iyy="2.470e-05" iyz="2.413e-05" izz="7.956e-05"/>
    </inertial>
  </link>
  <joint name="right_gripper_joint_09" type="revolute">
    <limit effort="0.35" lower="-0.19599999999999998" upper="1.6099999999999999" velocity="6.283"/>
    <axis xyz="0 1 0"/>
    <parent link="right_gripper_link_08"/>
    <child link="right_gripper_link_09"/>
    <origin xyz="0 0 0.0164"/>
    <dynamics damping="0.1" friction="0.01"/>
  </joint>
  <!-- [LINK 2, 6, 10]-->
  <link name="right_gripper_link_10">
    <visual>
      <geometry>
        <mesh filename="allegro_meshes/link_2_0.obj"/>
      </geometry>
    </visual>
    <collision>
      <geometry>
        <box size="0.0196 0.0275 0.0384"/>
      </geometry>
      <origin rpy="0 0 0" xyz="0 0 0.0192"/>
    </collision>
    <inertial>
      <mass value="0.0355"/>
      <origin rpy="0 0 0" xyz="0 0 0"/>
      <inertia ixx="2.639e-05" ixy="6.679e-06" ixz="4.783e-06" iyy="1.349e-05" iyz="9.372e-06" izz="2.639e-05"/>
    </inertial>
  </link>
  <joint name="right_gripper_joint_10" type="revolute">
    <axis xyz="0 1 0"/>
    <limit effort="0.35" lower="-0.17400000000000002" upper="1.7089999999999999" velocity="6.283"/>
    <parent link="right_gripper_link_09"/>
    <child link="right_gripper_link_10"/>
    <origin xyz="0 0 0.054"/>
    <dynamics damping="0.1" friction="0.01"/>
  </joint>
  <!-- [LINK 3, 7, 11] -->
  <link name="right_gripper_link_11">
    <visual>
      <geometry>
        <mesh filename="allegro_meshes/link_3_0.obj"/>
      </geometry>
    </visual>
    <collision>
      <geometry>
        <box size="0.0196 0.0275 0.0267"/>
      </geometry>
      <origin rpy="0 0 0" xyz="0 0 0.01335"/>
    </collision>
    <inertial>
      <mass value="0.0096"/>
      <origin rpy="0 0 0" xyz="0 0 0"/>
      <inertia ixx="4.701e-06" ixy="1.255e-06" ixz="1.293e-06" iyy="3.649e-06" iyz="1.762e-06" izz="4.701e-06"/>
    </inertial>
  </link>
  <joint name="right_gripper_joint_11" type="revolute">
    <axis xyz="0 1 0"/>
    <limit effort="0.35" lower="-0.227" upper="1.618" velocity="6.283"/>
    <parent link="right_gripper_link_10"/>
    <child link="right_gripper_link_11"/>
    <origin xyz="0 0 0.0384"/>
    <dynamics damping="0.1" friction="0.01"/>
  </joint>
  <!-- [FINGER TIP] -->
  <link name="right_gripper_link_11_tip">
    <visual>
      <geometry>
        <mesh filename="allegro_meshes/link_3_tip.stl"/>
      </geometry>
      <material name="white">
        <color rgba=".9 .9 .9 1"/>
      </material>
    </visual>
    <collision>
      <geometry>
        <sphere radius="0.012"/>
      </geometry>
    </collision>
    <inertial>
      <mass value="0.0168"/>
      <origin rpy="0 0 0" xyz="0 0 0"/>
      <inertia ixx="9.68e-07" ixy="0.0" ixz="0.0" iyy="9.68e-07" iyz="0.0" izz="9.68e-07"/>
    </inertial>
  </link>
  <joint name="right_gripper_joint_11_tip" type="fixed">
    <parent link="right_gripper_link_11"/>
    <child link="right_gripper_link_11_tip"/>
    <origin rpy="0 0 0" xyz="0 0 0.026699999999999998"/>
  </joint>
  <!-- [LINK 12] -->
  <link name="right_gripper_link_12">
    <visual>
      <geometry>
        <mesh filename="allegro_meshes/link_12_0_right.obj"/>
      </geometry>
      <origin rpy="0.0 0 0" xyz="0 0 0"/>
    </visual>
    <collision>
      <geometry>
        <box size="0.0358 0.034 0.0455"/>
      </geometry>
      <!-- RIGHT -->
      <origin rpy="0 0 0" xyz="-0.0179 0.009 0.0145"/>
      <!-- LEFT -->
      <!-- <origin rpy="0 0 0" xyz="${-0.0358/2+0.0} ${-.018/2} ${.029/2}"/> -->
    </collision>
    <inertial>
      <mass value="0.0176"/>
      <origin rpy="0 0 0" xyz="0 0 0"/>
      <inertia ixx="1.892e-05" ixy="7.167e-06" ixz="5.355e-06" iyy="1.430e-05" iyz="6.806e-06" izz="1.892e-05"/>
    </inertial>
  </link>
  <joint name="right_gripper_joint_12" type="revolute">
    <axis xyz="-1 0 0"/>
    <limit effort="0.35" lower="0.46299999999999997" upper="1.396" velocity="6.283"/>
    <parent link="right_gripper_palm_link"/>
    <child link="right_gripper_link_12"/>
    <origin rpy="0 -1.6580627884499999 -1.5707963259" xyz="-0.0182 0.019333 -0.045987"/>
    <dynamics damping="0.1" friction="0.01"/>
  </joint>
  <!-- [LINK 13] -->
  <link name="right_gripper_link_13">
    <visual>
      <geometry>
        <mesh filename="allegro_meshes/link_13_0.obj"/>
      </geometry>
    </visual>
    <collision>
      <geometry>
        <box size="0.0196 0.0275 0.0177"/>
      </geometry>
      <origin rpy="0 0 0" xyz="0 0 0.00885"/>
    </collision>
    <inertial>
      <mass value="0.0119"/>
      <origin rpy="0 0 0" xyz="0 0 0"/>
      <inertia ixx="4.242e-06" ixy="1.032e-06" ixz="1.603e-06" iyy="4.523e-06" iyz="1.448e-06" izz="4.242e-06"/>
    </inertial>
  </link>
  <joint name="right_gripper_joint_13" type="revolute">
    <axis xyz="0 0 1"/>
    <limit effort="0.35" lower="-0.10499999999999998" upper="1.1629999999999998" velocity="6.283"/>
    <parent link="right_gripper_link_12"/>
    <child link="right_gripper_link_13"/>
    <origin xyz="-0.027 0.005 0.0399"/>
    <dynamics damping="0.1" friction="0.01"/>
  </joint>
  <!-- [LINK 14] -->
  <link name="right_gripper_link_14">
    <visual>
      <geometry>
        <mesh filename="allegro_meshes/link_14_0.obj"/>
      </geometry>
    </visual>
    <collision>
      <geometry>
        <box size="0.0196 0.0275 0.0514"/>
      </geometry>
      <origin rpy="0 0 0" xyz="0 0 0.0257"/>
    </collision>
    <inertial>
      <mass value="0.038"/>
      <origin rpy="0 0 0" xyz="0 0 0"/>
      <inertia ixx="4.304e-05" ixy="9.570e-06" ixz="5.120e-06" iyy="1.444e-05" iyz="1.342e-05" izz="4.304e-05"/>
    </inertial>
  </link>
  <joint name="right_gripper_joint_14" type="revolute">
    <axis xyz="0 1 0"/>
    <limit effort="0.35" lower="-0.18899999999999997" upper="1.644" velocity="6.283"/>
    <parent link="right_gripper_link_13"/>
    <child link="right_gripper_link_14"/>
    <origin xyz="0 0 0.0177"/>
    <dynamics damping="0.1" friction="0.01"/>
  </joint>
  <!-- [LINK 15] -->
  <link name="right_gripper_link_15">
    <visual>
      <geometry>
        <mesh filename="allegro_meshes/link_15_0.obj"/>
      </geometry>
    </visual>
    <collision>
      <geometry>
        <box size="0.0196 0.0275 0.0423"/>
      </geometry>
      <origin rpy="0 0 0" xyz="0 0 0.02115"/>
    </collision>
    <inertial>
      <mass value="0.0388"/>
      <origin rpy="0 0 0" xyz="0 0 0"/>
      <inertia ixx="3.292e-05" ixy="8.042e-06" ixz="5.228e-06" iyy="1.474e-05" iyz="1.128e-05" izz="3.292e-05"/>
    </inertial>
  </link>
  <joint name="right_gripper_joint_15" type="revolute">
    <axis xyz="0 1 0"/>
    <limit effort="0.35" lower="-0.162" upper="1.719" velocity="6.283"/>
    <parent link="right_gripper_link_14"/>
    <child link="right_gripper_link_15"/>
    <origin xyz="0 0 0.0514"/>
    <dynamics damping="0.1" friction="0.01"/>
  </joint>
  <!-- [FINGER TIP] -->
  <link name="right_gripper_link_15_tip">
    <visual>
      <geometry>
        <mesh filename="allegro_meshes/link_15_tip.stl"/>
      </geometry>
      <material name="white">
        <color rgba=".9 .9 .9 1"/>
      </material>
    </visual>
    <collision>
      <geometry>
        <sphere radius="0.012"/>
      </geometry>
      <origin rpy="0 0 0" xyz="0 0 0"/>
    </collision>
    <inertial>
      <mass value="0.0168"/>
      <origin rpy="0 0 0" xyz="0 0 0"/>
      <inertia ixx="9.68e-07" ixy="0.0" ixz="0.0" iyy="9.68e-07" iyz="0.0" izz="9.68e-07"/>
    </inertial>
  </link>
  <joint name="right_gripper_joint_15_tip" type="fixed">
    <parent link="right_gripper_link_15"/>
    <child link="right_gripper_link_15_tip"/>
    <origin rpy="0 0 0" xyz="0 0 0.042300000000000004"/>
  </joint>
  <!-- ================================== SUPPORTS ================================== -->
  <link name="right_gripper_base_screws"/>
  <link name="right_gripper_ur5_attachment">
    <visual>
      <geometry>
        <mesh filename="support_meshes/UR5_attachment.stl" scale="0.001 0.001 0.001"/>
      </geometry>
      <material name="darker_grey">
        <color rgba="0.7 0.7 0.7 1"/>
      </material>
    </visual>
    <collision>
      <geometry>
        <mesh filename="support_meshes/UR5_attachment_bottom_collision.stl" scale="0.001 0.001 0.001"/>
      </geometry>
    </collision>
    <collision>
      <geometry>
        <mesh filename="support_meshes/UR5_attachment_top_collision.stl" scale="0.001 0.001 0.001"/>
      </geometry>
    </collision>
    <inertial>
      <mass value="0.2"/>
      <origin rpy="0  0  0" xyz="0.000 -0.000 0.015"/>
      <inertia ixx="1.01e-04" ixy="-1.20e-13" ixz="3.53e-13" iyy="1.04e-04" iyz="-4.03e-07" izz="1.17e-04"/>
    </inertial>
  </link>
  <!-- ================================== ORIGIN ================================== -->
  <joint name="right_gripper_base_screws_joint" type="fixed">
    <parent link="right_gripper_base_screws"/>
    <child link="right_gripper_palm_link"/>
    <origin rpy="0 0 1.5707963259" xyz="0 0.0093 0.095"/>
  </joint>
  <joint name="right_gripper_ur5_attachment_joint" type="fixed">
    <parent link="right_gripper_ur5_attachment"/>
    <child link="right_gripper_base_screws"/>
    <origin rpy="0 0 0" xyz="0 0 0.05"/>
  </joint>
  <joint name="right_gripper_parent_joint" type="fixed">
    <parent link="right_tool"/>
    <child link="right_gripper_ur5_attachment"/>
    <origin rpy="0.0 0.0 0.0" xyz="0.0 0.0 0.0"/>
  </joint>
</robot>
